<!DOCTYPE html>
<html lang="en">
<head>
    <meta charset="UTF-8">
    <meta name="viewport" content="width=device-width, initial-scale=1.0">
    <title>Async Await</title>
    <link rel="stylesheet" href="../base.css">
</head>
<body>
    <script>
        function wait(ms = 0)
        {
            return new Promise(resolve => {
                setTimeout(resolve,ms);
            });
        }

        // async function go(){
        //     // await will pause the function until the promise has been resolve.
        //     console.log("Starting");
        //     await wait(2000);   // await is only valid and use with async functions.
        //     console.log("running");
        //     await wait(200);
        //     console.log("ending");
        // }

        function makePizza(toppings) {
            return new Promise(function (resolve, reject) {
                // reject if people try with pineapple
                if (toppings.includes('pineapple')) {
                    reject('Seriously? Get out 🍍');
                }
                const amountOfTimeToBake = 500 + (toppings.length * 200);

                // wait for one second.
                setTimeout(function () {
                    // when we are ready we can resolve the promise.
                    resolve(`pizza with ${toppings.join(' ')} toppings is ready`);
                }, amountOfTimeToBake);

                // if something is wrong than we can reject the promise.
            });
        }

        function handleError(err){
            console.log("Ohh no");
            console.log(err);
        }

        // async function returns a promise while the normal function returns the data.
        // so we can use catch to handle the promise or error from the async function.
        async function go(){
            // method-1 try catch block
            // try {
            //     const pizza = await makePizza(['pineapple']);
            // } catch (error) {
            //     console.log("whats this ?");
            //     console.log(error);
            // }

            // method-2 use the syntax of promise to catch the error.
            //const pizza = await makePizza(['pineapple']).catch(handleError);
            const pizza = await makePizza(['pineapple']);
            console.log(pizza);
            return pizza;
        }

        // catch it at runtime
        // useful way.
        go().catch(handleError);    // we can also add catch to the calling of the function.

        // go().then(result => {
        //     console.log(result);
        // }).catch(handleError);


        async function goGo(){
            const result = await go();  // awaiting async function.
        }

        goGo().catch(handleError);

        //--

        // make a safe function with a higher order function.
        function makeSafe(fn,handleError){
            return function(){
                fn().catch(handleError);
            }
        }

        const safeGo = makeSafe(go,handleError);
        safeGo();

    </script>
</body>
</html>